Workbook

Sheet Legenda
A1: BuddyKids — Matrice di Test
A2: Guida alla compilazione della colonna Esito
A4: Colonna | B4: Significato
A5: Esito = OK | B5: Il test e stato eseguito e il comportamento corrisponde al risultato atteso.
A6: Esito = BUG | B6: Il comportamento non corrisponde a quanto previsto per un errore tecnico (crash, dato sbagliato, funzione che non risponde). Genera automaticamente un ID 'BUG-TC-xxx' in colonna ID Anomalia.
A7: Esito = FUNCTIONAL | B7: Il comportamento e quello atteso OGGI, ma manca un requisito/funzionalita non ancora costruita (non e un errore, e un gap di scope). Genera automaticamente un ID 'FUNCTIONAL-TC-xxx'.
A8: Esito = DA TESTARE | B8: Non ancora verificato sul deploy reale — da compilare durante il test.
A9: Priorita | B9: Alta = blocca un flusso centrale (registrazione, prenotazione, pagamento simulato, sicurezza ruoli). Media = funzionalita secondaria ma visibile. Bassa = rifinitura/nice-to-have.
A10: Task collegato | B10: Riferimento al numero di task interno gia tracciato in questa conversazione, quando applicabile.
A11: Note | B11: Ipotesi/diagnosi gia note dal codice sorgente (utile per non re-investigare da zero) o dettagli aggiuntivi.
A13: Ordine di test consigliato
A14: 1. Setup — crea le tre utenze (genitore, gestore, admin) prima di tutto il resto.
A15: 2. Genitori — Home, Cerca, Attivita, Prenotazione.
A16: 3. Genitori — Gruppi (crea gruppo, invita una seconda utenza genitore reale per testare davvero l'adesione multi-famiglia) e Accompagnamento.
A17: 4. Gestore — ricevi e rispondi alla Richiesta Gruppo generata al punto 3.
A18: 5. Gestore — Attivita/Promozioni/Profilo centro.
A19: 6. Admin — Dashboard/Gestione/Analytics/Richieste Gruppo/Tag.
A20: 7. Multi-tenant/PWA — per ultimo, richiede i tre alias/domini pubblicati.

Sheet Test Case
A1: ID Test | B1: Area | C1: Scenario | D1: Precondizioni | E1: Passi | F1: Risultato atteso | G1: Esito | H1: ID Anomalia | I1: Priorita | J1: Task collegato | K1: STATO ANOMALIA | L1: Note
A2: TC-001 | B2: Setup | C2: Registrazione nuovo account genitore | D2: Nessun account con quella email | E2: Vai su /auth/login -> tab 'Registrati' -> inserisci email+password (min 6 caratteri) -> invia | F2: Messaggio 'Controlla la tua email per confermare la registrazione'; riga creata in public.profiles con role='parent' | G2: OK | H2: =IF(G2="BUG","BUG-"&A2,IF(G2="FUNCTIONAL","FUNCTIONAL-"&A2,"")) | I2: Alta | K2: FIX (messaggio post-registrazione già mostrato in pagina, verificato nel codice) / NON-CODICE (dominio email invio - vedi task #53, azione su dashboard Supabase, non da codice) | L2: 1) Dopo aver inserito email e password, la pagina dovrebbe aggiornarsi mentre rimane sul login 2) la mail, ora, arriva da supabase: segnarsi di sistemare tutte le mail con indirizzi e domini corretti
A3: TC-002 | B3: Setup | C3: Conferma email e primo accesso | D3: Registrazione completata (TC precedente) | E3: Apri il link di conferma ricevuto via email -> verifica redirect su /auth/callback -> poi login con email+password | F3: Login riuscito, redirect a '/' | G3: OK | H3: =IF(G3="BUG","BUG-"&A3,IF(G3="FUNCTIONAL","FUNCTIONAL-"&A3,"")) | I3: Alta
A4: TC-003 | B4: Setup | C4: Login con credenziali errate | D4: Account esistente | E4: Vai su /auth/login -> inserisci password sbagliata -> invia | F4: Messaggio di errore visibile, nessun accesso | G4: BUG | H4: =IF(G4="BUG","BUG-"&A4,IF(G4="FUNCTIONAL","FUNCTIONAL-"&A4,"")) -> BUG-TC-003 | I4: Media | K4: TO DEPLOY (fixato in questa sessione: messaggi di errore login tradotti in italiano) | RISOLTO: bug label email/password non associate, vedi Note | RISOLTO (hardening test) | L4: Viene mostrato messaggio "Invalid login credentials" - inserire messaggio parlante user friendly | Bug trovato nella prima esecuzione reale della suite: le label Email/Password in LoginForm.tsx non erano associate (mancava htmlFor/id) agli input, quindi getByLabel() non trovava mai i campi e ogni test con login reale andava in timeout — causa di ~70 fallimenti in un solo run. Corretto aggiungendo htmlFor/id a Email, Password e Codice invito in LoginForm.tsx. | RUN REALE: fallimento sporadico su mobile-chrome (messaggio non trovato entro 10s) — probabile rate limit Supabase Auth (molti login paralleli, fullyParallel:true) invece del messaggio 'non corrette'. Regex del test ampliata per coprire anche 'troppi tentativi', timeout alzato a 15s.
A5: TC-004 | B5: Setup | C5: Password dimenticata | D5: Nessuna | E5: Click su 'Password dimenticata?' in /auth/login | F5: Dovrebbe avviare un flusso di reset password | G5: FUNCTIONAL | H5: =IF(G5="BUG","BUG-"&A5,IF(G5="FUNCTIONAL","FUNCTIONAL-"&A5,"")) -> FUNCTIONAL-TC-004 | I5: Bassa | J5: #11 area affine | K5: TO DEPLOY (fixato in questa sessione: reset password reale via Supabase) | L5: Noto: badge ComingSoon, nessuna azione reale implementata
A6: TC-005 | B6: Setup | C6: Promozione account a Gestore centro | D6: Account genitore registrato, accesso allo SQL Editor Supabase | E6: Esegui: update public.profiles set role='center_admin', center_id=(select id from centers where slug='...') where email='...' | F6: Il profilo ha role=center_admin e center_id valorizzato | G6: DA TESTARE | H6: =IF(G6="BUG","BUG-"&A6,IF(G6="FUNCTIONAL","FUNCTIONAL-"&A6,"")) | I6: Alta | K6: PARZIALE: TO DEPLOY (branding pagina login + CTA logout fixati) / NOT CLEAR (creazione account self-service senza SQL - task #44, serve tua decisione su workflow di approvazione) | L6: Test case tecnico - da riformulare con processo "utente" senza accesso ai db o conoscenza dell'infrastruttura tecnica Bisogna prevedere creazione account separata da quella del genitore, sono processi e flussi distinti. Anche l'homepage di autenticazione deve riportare colori e layout dell'app "Partner" e non come ora, quella dei genitori. Modificare CTA "Torna all'app" con "Esci dall'account" o simile.
A7: TC-006 | B7: Setup | C7: Login Gestore su dominio partner/alias | D7: Account promosso (TC precedente) | E7: Vai sull'alias/dominio partner -> login -> verifica redirect a /center | F7: Accesso alla dashboard Gestore, sidebar con Dashboard/Il mio centro/Attivita/Promozioni/Richieste Gruppo | G7: DA TESTARE | H7: =IF(G7="BUG","BUG-"&A7,IF(G7="FUNCTIONAL","FUNCTIONAL-"&A7,"")) | I7: Alta | J7: #6 | K7: TO DEPLOY (fixato: login tenant-aware, redirect corretto)
A8: TC-007 | B8: Setup | C8: Promozione account ad Admin piattaforma | D8: Account genitore registrato | E8: Esegui: update public.profiles set role='platform_admin' where email='...' | F8: Il profilo ha role=platform_admin | G8: DA TESTARE | H8: =IF(G8="BUG","BUG-"&A8,IF(G8="FUNCTIONAL","FUNCTIONAL-"&A8,"")) | I8: Alta | K8: PARZIALE: TO DEPLOY (branding pagina login + CTA logout fixati) / NOT CLEAR (creazione account self-service senza SQL - task #44, serve tua decisione) | L8: Test case tecnico - da riformulare con processo "utente" senza accesso ai db o conoscenza dell'infrastruttura tecnica Bisogna prevedere creazione account separata da quella del genitore, sono processi e flussi distinti. Anche l'homepage di autenticazione deve riportare colori e layout dell'app "Admin" e non come ora, quella dei genitori. Modificare CTA "Torna all'app" con "Esci dall'account" o simile
A9: TC-008 | B9: Setup | C9: Login Admin su dominio admin/alias | D9: Account promosso (TC precedente) | E9: Vai sull'alias/dominio admin -> login -> verifica redirect a /admin | F9: Accesso alla dashboard Admin | G9: DA TESTARE | H9: =IF(G9="BUG","BUG-"&A9,IF(G9="FUNCTIONAL","FUNCTIONAL-"&A9,"")) | I9: Alta | J9: #8 | K9: TO DEPLOY (fixato: login tenant-aware, redirect corretto)
A10: TC-009 | B10: Setup | C10: Accesso negato a /center con ruolo parent | D10: Account con role=parent | E10: Vai sul dominio partner e prova ad accedere | F10: Se non loggato: redirect a login sullo stesso host; se loggato come parent: redirect al dominio principale | G10: DA TESTARE | H10: =IF(G10="BUG","BUG-"&A10,IF(G10="FUNCTIONAL","FUNCTIONAL-"&A10,"")) | I10: Alta | K10: NOT CLEAR (nota è sulla riformulazione del test, non un bug applicativo - legato a #44) | L10: Test case tecnico - da riformulare con processo "utente" senza accesso ai db o conoscenza dell'infrastruttura tecnica
A11: TC-010 | B11: Setup | C11: Accesso negato a /admin con ruolo center_admin | D11: Account con role=center_admin | E11: Vai sul dominio admin e prova ad accedere | F11: Redirect al dominio principale (l'admin e' superset, il gestore no) | G11: DA TESTARE | H11: =IF(G11="BUG","BUG-"&A11,IF(G11="FUNCTIONAL","FUNCTIONAL-"&A11,"")) | I11: Alta | K11: NOT CLEAR (nota è sulla riformulazione del test, non un bug applicativo - legato a #44) | L11: Test case tecnico - da riformulare con processo "utente" senza accesso ai db o conoscenza dell'infrastruttura tecnica
A12: TC-011 | B12: Setup | C12: Logout | D12: Utente loggato (qualsiasi ruolo) | E12: Vai su Profilo (genitore) o link in sidebar (gestore/admin) -> click 'Esci' | F12: Sessione terminata, redirect a login o home pubblica | G12: DA TESTARE | H12: =IF(G12="BUG","BUG-"&A12,IF(G12="FUNCTIONAL","FUNCTIONAL-"&A12,"")) | I12: Media
A13: TC-012 | B13: Genitori - Home | C13: Home mostra attivita reali | D13: Almeno un'attivita inserita in Supabase | E13: Login come genitore -> apri '/' | F13: Le card 'Popolari' mostrano attivita reali dal DB, non i dati demo | G13: FUNCTIONAL | H13: =IF(G13="BUG","BUG-"&A13,IF(G13="FUNCTIONAL","FUNCTIONAL-"&A13,"")) -> FUNCTIONAL-TC-012 | I13: Alta | J13: #3 | K13: PARZIALE: TO DEPLOY (ordinamento interim su rating/recensioni reali fixato) / NOT CLEAR (definizione di business di cosa rende un'attività "Popolare" - serve tua decisione) | L13: Inserire TC per creazione - lato Partner - dell'attività. Specificare funzionalmente come deve essere resa "Popolare" una attività
A14: TC-013 | B14: Genitori - Home | C14: Filtro categoria in Home | D14: Nessuna | E14: Su Home, clicca una categoria (es. Sport) -> poi 'Tutte' | F14: Le card mostrate cambiano in base al tag selezionato; 'Tutte' ripristina la lista intera | G14: BUG | H14: =IF(G14="BUG","BUG-"&A14,IF(G14="FUNCTIONAL","FUNCTIONAL-"&A14,"")) -> BUG-TC-013 | I14: Alta | J14: #30 | K14: AGGIORNATO: la vecchia UI Home "Popolari vicino a te" con filtro categoria e stata sostituita dal toggle Planner/Per bambino; test riscritto per verificare il chip Sport dentro Per bambino > Categorie (vedi HomeFeed.tsx / PerBambinoView.tsx). | RISOLTO | L14: BUG DI TEST TROVATO+CORRETTO (run reale): la regex /border-sky/ matchava anche la classe statica 'hover:border-sky' presente nel chip NON selezionato (CategoryChip.tsx), quindi l'assert 'non selezionato' falliva sempre. Corretta con lookbehind negativo (?<!hover:)border-sky\b.
A15: TC-014 | B15: Genitori - Home | C15: Geolocalizzazione Home | D15: Permessi posizione del browser concessi | E15: Clicca 'Attivita sulla mappa' / 'Usa posizione' -> concedi permesso | F15: Il testo mostra un conteggio reale di centri entro 5 km (non piu fisso a 24) | G15: ENHANCEMENT | H15: =IF(G15="BUG","BUG-"&A15,IF(G15="FUNCTIONAL","FUNCTIONAL-"&A15,"")) | I15: Media | J15: #30 | K15: TO DEPLOY (fixato: la posizione rilevata resta salvata tra Home e Cerca in questa sessione) | L15: La geolocalizzazione funziona, ma ogni volta riappare la CTA "Usa posizione" dopo qualsiasi passaggio. Bisogna rivedere la UX
A16: TC-015 | B16: Genitori - Home | C16: Geolocalizzazione negata | D16: Nessuna | E16: Clicca 'Usa posizione' -> nega il permesso | F16: Messaggio di errore leggibile, l'app non si blocca | G16: ENHANCEMENT | H16: =IF(G16="BUG","BUG-"&A16,IF(G16="FUNCTIONAL","FUNCTIONAL-"&A16,"")) | I16: Bassa | K16: PARZIALE: TO DEPLOY (messaggio di errore migliorato) / NOT CLEAR (il browser blocca la ri-richiesta del popup nativo dopo un rifiuto per policy di sicurezza - limite del browser, non risolvibile lato app) | L16: Funziona: "Non è stato possibile ottenre la posizione - controlla i permessi" e la CTA rimane "Usa la posizione". Se possibile deve riapparire il pop-up di chrome per richiedere accesso ai dati di geolocalizzazione
A17: TC-016 | B17: Genitori - Cerca | C17: Ricerca testuale | D17: Nessuna | E17: Vai su /search -> digita il nome di un'attivita esistente | F17: Solo le attivita corrispondenti restano in lista | G17: BUG | H17: =IF(G17="BUG","BUG-"&A17,IF(G17="FUNCTIONAL","FUNCTIONAL-"&A17,"")) -> BUG-TC-016 | I17: Alta | K17: TO DEPLOY (Azzera ora sempre visibile; azzeramento per singolo filtro non ancora implementato - solo azzeramento globale) | RISOLTO | L17: Funziona. Manca - su tutti i filtri - la possibilità di cancellare il filtro applicato | BUG DI TEST TROVATO+CORRETTO (run reale): l'assert finale era invertita (.not.toHaveText invece di .toHaveText) — svuotare la ricerca deve ripristinare lo STESSO conteggio iniziale, non uno diverso.
A18: TC-017 | B18: Genitori - Cerca | C18: Filtro Eta | D18: Nessuna | E18: Apri filtro 'Eta' -> sposta gli slider min/max | F18: La lista si aggiorna mostrando solo attivita compatibili con la fascia | G18: ENHANCEMENT | H18: =IF(G18="BUG","BUG-"&A18,IF(G18="FUNCTIONAL","FUNCTIONAL-"&A18,"")) | I18: Media | J18: #31 | K18: TO DEPLOY (fixato: due campi numerici da/a al posto degli slider sovrapposti) | L18: Funziona: rivedrei solo l'UX della selezione della fascia d'età che non è facilmente comprensibile. Forse unica striscia con pallino di età minima e pallino di età massima? O anche campo testuale? Manca - su tutti i filtri - la possibilità di cancellare il filtro applicato
A19: TC-018 | B19: Genitori - Cerca | C19: Filtro Prezzo | D19: Nessuna | E19: Apri filtro 'Prezzo' -> abbassa il tetto massimo | F19: Scompaiono le attivita piu costose del tetto | G19: OK | H19: =IF(G19="BUG","BUG-"&A19,IF(G19="FUNCTIONAL","FUNCTIONAL-"&A19,"")) | I19: Media | J19: #31 | K19: TO DEPLOY (Azzera ora sempre visibile; azzeramento per singolo filtro non ancora implementato) | L19: Funziona. Manca - su tutti i filtri - la possibilità di cancellare il filtro applicato
A20: TC-019 | B20: Genitori - Cerca | C20: Filtro Zona (testo) | D20: Nessuna | E20: Apri filtro 'Zona' -> digita una via/quartiere presente in un indirizzo | F20: Restano solo le attivita con quell'indirizzo/centro | G20: ENHANCEMENT | H20: =IF(G20="BUG","BUG-"&A20,IF(G20="FUNCTIONAL","FUNCTIONAL-"&A20,"")) | I20: Media | J20: #31 | K20: TO DEPLOY (fixato: autocomplete zona con sole vie/zone/comuni, esclusi nomi di centri/attività) | L20: Funziona. La ricerca per "Zona" deve avere una lista di comuni, quartieri, zone che si autocompilano Manca - su tutti i filtri - la possibilità di cancellare il filtro applicato
A21: TC-020 | B21: Genitori - Cerca | C21: Filtro Servizi - Bar | D21: Almeno un centro con 'Bar' attivato nel profilo | E21: Apri filtro 'Servizi' -> seleziona 'Bar nel centro' | F21: Restano solo le attivita di centri con has_bar=true | G21: OK | H21: =IF(G21="BUG","BUG-"&A21,IF(G21="FUNCTIONAL","FUNCTIONAL-"&A21,"")) | I21: Alta | J21: #31 | K21: TO DEPLOY (Azzera ora sempre visibile; azzeramento per singolo filtro non ancora implementato) | L21: Funziona. Manca - su tutti i filtri - la possibilità di cancellare il filtro applicato
A22: TC-021 | B22: Genitori - Cerca | C22: Filtro Servizi - Pranzo/Pre/Post | D22: Nessuna | E22: Seleziona singolarmente Pranzo incluso / Pre-scuola / Post-scuola | F22: La lista si filtra coerentemente con i campi dell'attivita | G22: ENHANCEMENT | H22: =IF(G22="BUG","BUG-"&A22,IF(G22="FUNCTIONAL","FUNCTIONAL-"&A22,"")) | I22: Media | J22: #31 | K22: TO DEPLOY (fixato: sezione Servizi disponibili nel dettaglio attività) | L22: Funziona. Nella scheda di dettaglio dell'attività devono essere mostrati in maniera chiara sintetica e veloce i servizi disponibili altrimenti non c'è modo di avere conferma della selezione corretta
A23: TC-022 | B23: Genitori - Cerca | C23: Azzeramento filtri | D23: Uno o piu filtri attivi | E23: Clicca 'Azzera (N)' | F23: Tutti i filtri tornano al default e il pulsante scompare | G23: ENHANCEMENT | H23: =IF(G23="BUG","BUG-"&A23,IF(G23="FUNCTIONAL","FUNCTIONAL-"&A23,"")) | I23: Bassa | K23: TO DEPLOY (fixato: Azzera sempre visibile e chiude anche il pannello aperto) | L23: Funziona. La CTA "Azzera" deve essere visibile sempre - e una volta cliccata deve riportare allo staot iniziale la pagina "Cerca" (nel test fatto, avevo il tab "Servizi" esploso, ed è rimasto aperto anche dopo "azzera")
A24: TC-023 | B24: Genitori - Cerca | C24: Ricerca con geolocalizzazione da Home | D24: Aver cliccato 'Usa posizione' in Home | E24: Da Home, dopo la geolocalizzazione, clicca 'Vedi in Cerca' | F24: Si apre /search?lat=..&lng=.. con distanze reali calcolate e badge 'Vicino a te' | G24: BUG | H24: =IF(G24="BUG","BUG-"&A24,IF(G24="FUNCTIONAL","FUNCTIONAL-"&A24,"")) -> BUG-TC-023 | I24: Media | J24: #30 | K24: PARZIALE: TO DEPLOY (raggio filtro coerente Home->Cerca, coordinate rilevate ora visibili) / DA COSTRUIRE (mappa reale con pin spostabile - task #51, sbloccata: scelto Leaflet/OSM gratuito, ancora da costruire) | L24: Cliccando sulla CTA "Vedi in cerca" sembra perdersi il filtro sulla geolocalizzazione (prima mi dava in home 0 centri - giusto - poi riappaiono tutti in "Cerca"). Deve rimanere attivo il filtro geo applicato. Da rendere visibile anche il punto di geolocalizzazione in alto alla lista, in modo da controllare se è corretto. La mappa deve dare la possibilità di spostare il PIN qualora sia posizionato in modo sbagliato
A25: TC-024 | B25: Genitori - Cerca | C25: Filtro Date | D25: Nessuna | E25: Clicca il chip 'Date' | F25: Dovrebbe aprire un filtro per data/settimana | G25: DA TESTARE | H25: =IF(G25="BUG","BUG-"&A25,IF(G25="FUNCTIONAL","FUNCTIONAL-"&A25,"")) | I25: Bassa | K25: RISOLTO | L25: NOT CLEAR risolto con decisione di Fabrizio: il filtro Date ora seleziona una delle 13 settimane stagionali e filtra i risultati a chi ha REALMENTE posti liberi in quell'intervallo (activity_weeks.spots_left > 0), non solo un'etichetta ComingSoon. Pre-applicato anche arrivando dal Planner con ?week= (vedi TC-158).
A26: TC-025 | B26: Genitori - Attivita | C26: Apertura scheda attivita | D26: Nessuna | E26: Da Home o Cerca, clicca una card | F26: Si apre /activity/[slug] con dati reali (prezzo, eta, descrizione, tag) | H26: =IF(G26="BUG","BUG-"&A26,IF(G26="FUNCTIONAL","FUNCTIONAL-"&A26,"")) | I26: Alta
A27: TC-026 | B27: Genitori - Attivita | C27: Preferiti (cuore) | D27: Nessuna | E27: Sulla card o nel dettaglio, clicca l'icona cuore, poi ricarica la pagina | F27: Lo stato del preferito dovrebbe restare salvato dopo il reload | G27: BUG | H27: =IF(G27="BUG","BUG-"&A27,IF(G27="FUNCTIONAL","FUNCTIONAL-"&A27,"")) -> BUG-TC-026 | I27: Alta | J27: #21 | K27: DA COSTRUIRE (task #21, V1 - non ancora iniziato) | RISOLTO | L27: Noto: torna sempre allo stato iniziale al reload (solo useState locale, non salvato) | BUG DI TEST TROVATO+CORRETTO (run reale): DetailClient.tsx inizializza il preferito con useState(true) (parte sempre pieno), non useState(false) come assunto — dopo reload torna pieno, non vuoto. Test corretto per riflettere il comportamento reale (il gap di persistenza resta, ma il valore di default e' 'preferito').
A28: TC-027 | B28: Genitori - Attivita | C28: Recensioni | D28: Attivita con prenotazioni concluse | E28: Apri il dettaglio di un'attivita | F28: Ci si aspetta di vedere eventuali recensioni reali dei genitori | G28: FUNCTIONAL | H28: =IF(G28="BUG","BUG-"&A28,IF(G28="FUNCTIONAL","FUNCTIONAL-"&A28,"")) -> FUNCTIONAL-TC-027 | I28: Media | J28: #13 | K28: DA COSTRUIRE (task #13, V1 - non ancora iniziato) | L28: Noto: sezione recensioni sempre vuota, non ancora collegata a dati reali
A29: TC-028 | B29: Genitori - Attivita | C29: Promozioni attive visibili | D29: Il gestore ha creato una promozione attiva | E29: Apri il dettaglio dell'attivita promozionata | F29: Il badge/sconto della promozione e visibile ai genitori | H29: =IF(G29="BUG","BUG-"&A29,IF(G29="FUNCTIONAL","FUNCTIONAL-"&A29,"")) | I29: Media
A30: TC-029 | B30: Genitori - Prenotazione | C30: Prenotazione completa | D30: Attivita con settimane disponibili, almeno un bambino inserito | E30: Apri attivita -> 'Prenota' -> step 1 scegli settimane -> step 2 scegli bambino/i -> step 3 scegli pagamento -> conferma | F30: Prenotazione creata in Supabase (bookings/booking_weeks/booking_kids), redirect a schermata di successo | H30: =IF(G30="BUG","BUG-"&A30,IF(G30="FUNCTIONAL","FUNCTIONAL-"&A30,"")) | I30: Alta
A31: TC-030 | B31: Genitori - Prenotazione | C31: Sconto multi-settimana | D31: Prenotazione con 2+ settimane selezionate | E31: Seleziona 2 o piu settimane nello step 1 | F31: Il totale mostra la riga 'Sconto multi-settimana' -5% calcolata sul subtotale (settimane x prezzo x bambini) | H31: =IF(G31="BUG","BUG-"&A31,IF(G31="FUNCTIONAL","FUNCTIONAL-"&A31,"")) | I31: Media | J31: #36
A32: TC-031 | B32: Genitori - Prenotazione | C32: Sconto famiglia 2+ bambini | D32: Almeno 2 bambini salvati nel profilo | E32: Nello step 2, seleziona 2 o piu bambini per la stessa prenotazione | F32: Il totale mostra 'Sconto famiglia' pari a -10% sul 2 bambino, -15% sul 3, -20% dal 4 in poi (rispetto al prezzo pieno di un bambino); il subtotale e moltiplicato per il numero di bambini selezionati | H32: =IF(G32="BUG","BUG-"&A32,IF(G32="FUNCTIONAL","FUNCTIONAL-"&A32,"")) | I32: Alta | J32: #36 | L32: Feature nuova: verificare anche che si sommi correttamente allo sconto multi-settimana (vedi tema aperto sulla cumulabilita)
A33: TC-032 | B33: Genitori - Prenotazione | C33: Aggiunta bambino durante la prenotazione | D33: Nessun bambino ancora salvato | E33: Nello step 2, clicca 'Aggiungi bambino' e compila il form | F33: Il bambino viene salvato e selezionabile subito, il totale si aggiorna | H33: =IF(G33="BUG","BUG-"&A33,IF(G33="FUNCTIONAL","FUNCTIONAL-"&A33,"")) | I33: Media
A34: TC-033 | B34: Genitori - Prenotazione | C34: Pagamento (simulato) | D34: Prenotazione in corso, step 3 | E34: Scegli un metodo di pagamento e conferma | F34: Testo esplicito 'Pagamento simulato a scopo dimostrativo' nella schermata di successo, nessun addebito reale | G34: OK | H34: =IF(G34="BUG","BUG-"&A34,IF(G34="FUNCTIONAL","FUNCTIONAL-"&A34,"")) | I34: Alta | J34: #14 | L34: Atteso in questa fase: i pagamenti reali sono pianificati come ultimo step
A35: TC-034 | B35: Genitori - Prenotazione | C35: Rimando ad Andiamo Insieme nello step prenotazione | D35: Nessuna | E35: Nello step 2 di prenotazione, osserva la sezione 'Andiamo Insieme' | F35: Badge ComingSoon visibile | G35: FUNCTIONAL | H35: =IF(G35="BUG","BUG-"&A35,IF(G35="FUNCTIONAL","FUNCTIONAL-"&A35,"")) -> FUNCTIONAL-TC-034 | I35: Bassa | K35: NOT CLEAR (valutare se rimuovere/rimandare al gruppo - decisione di design, non urgente) | L35: Valutare se rimandare direttamente alla pagina Gruppo ora che l'Accompagnamento esiste li
A36: TC-035 | B36: Genitori - Gruppi | C36: Creazione gruppo | D36: Login genitore | E36: Vai su /groups -> '+ Nuovo' -> inserisci nome -> 'Crea gruppo' | F36: Il gruppo appare nella lista 'I miei gruppi', utente aggiunto come primo membro | G36: BUG | H36: =IF(G36="BUG","BUG-"&A36,IF(G36="FUNCTIONAL","FUNCTIONAL-"&A36,"")) -> BUG-TC-035 | I36: Alta | K36: RISOLTO | L36: Bug trovato durante l'automazione test: il test Playwright navigava su /groups senza sessione autenticata (un TODO diceva di aggiungere il login ma non era mai stato fatto), quindi il pulsante '+ Nuovo' non compariva mai (timeout). Corretto aggiungendo loginAs(page, 'parent') prima della navigazione in tests/genitori/gruppi.spec.ts.
A37: TC-036 | B37: Genitori - Gruppi | C37: Apertura dettaglio gruppo | D37: Gruppo creato | E37: Clicca sulla card del gruppo ('Apri gruppo') | F37: Si apre /groups/[id] con nome, pulsante Invita famiglie, tab Bambini&Richiesta e Accompagnamento | H37: =IF(G37="BUG","BUG-"&A37,IF(G37="FUNCTIONAL","FUNCTIONAL-"&A37,"")) | I37: Alta
A38: TC-037 | B38: Genitori - Gruppi | C38: Collegamento attivita al gruppo | D38: Sei il creatore del gruppo, nessuna attivita ancora collegata | E38: Nella pagina gruppo, 'Scegli attivita' -> seleziona dalla lista -> 'Conferma' | F38: L'header del gruppo mostra il nome attivita e centro collegati | H38: =IF(G38="BUG","BUG-"&A38,IF(G38="FUNCTIONAL","FUNCTIONAL-"&A38,"")) | I38: Alta
A39: TC-038 | B39: Genitori - Gruppi | C39: Invito ad altre famiglie | D39: Gruppo creato | E39: Click 'Invita famiglie' -> condividi o copia il link generato (/groups/join/[id]) | F39: Il link viene copiato/condiviso correttamente; su mobile con Web Share API si apre il menu di condivisione nativo | H39: =IF(G39="BUG","BUG-"&A39,IF(G39="FUNCTIONAL","FUNCTIONAL-"&A39,"")) | I39: Alta | L39: Feature nuova, verificare anche il messaggio 'Link copiato!' quando non c'e Web Share API
A40: TC-039 | B40: Genitori - Gruppi | C40: Adesione a un gruppo tramite link di invito | D40: Link di invito valido, secondo account genitore | E40: Apri il link /groups/join/[id] da un altro account (loggato) -> click 'Unisciti al gruppo' | F40: L'utente diventa membro del gruppo e viene reindirizzato a /groups/[id] con accesso completo | H40: =IF(G40="BUG","BUG-"&A40,IF(G40="FUNCTIONAL","FUNCTIONAL-"&A40,"")) | I40: Alta
...

Sheet Riepilogo
A1: Riepilogo per Esito
A2: Esito | B2: Conteggio | D2: Area | E2: N. test
A3: OK | B3: =COUNTIF('Test Case'!G:G,"OK") -> 17 | D3: Setup | E3: =COUNTIF('Test Case'!B:B,"Setup") -> 11
A4: BUG | B4: =COUNTIF('Test Case'!G:G,"BUG") -> 12 | D4: Genitori - Home | E4: =COUNTIF('Test Case'!B:B,"Genitori - Home") -> 12
A5: FUNCTIONAL | B5: =COUNTIF('Test Case'!G:G,"FUNCTIONAL") -> 18 | D5: Genitori - Cerca | E5: =COUNTIF('Test Case'!B:B,"Genitori - Cerca") -> 12
A6: DA TESTARE | B6: =COUNTIF('Test Case'!G:G,"DA TESTARE") -> 359 | D6: Genitori - Attivita | E6: =COUNTIF('Test Case'!B:B,"Genitori - Attivita") -> 16
A7: Totale test case | B7: =COUNTA('Test Case'!A2:A10000) -> 498 | D7: Genitori - Prenotazione | E7: =COUNTIF('Test Case'!B:B,"Genitori - Prenotazione") -> 17
D8: Genitori - Gruppi | E8: =COUNTIF('Test Case'!B:B,"Genitori - Gruppi") -> 17
D9: Gestore - Richieste Gruppo | E9: =COUNTIF('Test Case'!B:B,"Gestore - Richieste Gruppo") -> 4
D10: Genitori - Accompagnamento | E10: =COUNTIF('Test Case'!B:B,"Genitori - Accompagnamento") -> 8
D11: Genitori - Calendario | E11: =COUNTIF('Test Case'!B:B,"Genitori - Calendario") -> 2
D12: Genitori - Profilo | E12: =COUNTIF('Test Case'!B:B,"Genitori - Profilo") -> 23
D13: Gestore - Dashboard | E13: =COUNTIF('Test Case'!B:B,"Gestore - Dashboard") -> 4
D14: Gestore - Attivita | E14: =COUNTIF('Test Case'!B:B,"Gestore - Attivita") -> 9
D15: Gestore - Promozioni | E15: =COUNTIF('Test Case'!B:B,"Gestore - Promozioni") -> 2
D16: Gestore - Profilo Centro | E16: =COUNTIF('Test Case'!B:B,"Gestore - Profilo Centro") -> 4
D17: Admin - Dashboard | E17: =COUNTIF('Test Case'!B:B,"Admin - Dashboard") -> 2
D18: Admin - Gestione | E18: =COUNTIF('Test Case'!B:B,"Admin - Gestione") -> 7
D19: Admin - Richieste Gruppo | E19: =COUNTIF('Test Case'!B:B,"Admin - Richieste Gruppo") -> 1
D20: Admin - Analytics | E20: =COUNTIF('Test Case'!B:B,"Admin - Analytics") -> 3
D21: Multi-tenant / PWA | E21: =COUNTIF('Test Case'!B:B,"Multi-tenant / PWA") -> 7
D22: Fuori scope attuale | E22: =COUNTIF('Test Case'!B:B,"Fuori scope attuale") -> 3
D23: Genitori - Home (Planner/Per Bambino) | E23: =COUNTIF('Test Case'!B:B,"Genitori - Home (Planner/Per Bambino)") -> 14
D24: Gestore - Inviti | E24: =COUNTIF('Test Case'!B:B,"Gestore - Inviti") -> 6
D25: Genitori - Registrazione | E25: =COUNTIF('Test Case'!B:B,"Genitori - Registrazione") -> 2
D26: Gestore - Le mie richieste | E26: =COUNTIF('Test Case'!B:B,"Gestore - Le mie richieste") -> 4
D27: Gestore - Report presenze | E27: =COUNTIF('Test Case'!B:B,"Gestore - Report presenze") -> 2
D28: Admin - Nuovi pannelli | E28: =COUNTIF('Test Case'!B:B,"Admin - Nuovi pannelli") -> 3
D29: Gestore - Account | E29: =COUNTIF('Test Case'!B:B,"Gestore - Account") -> 1
D30: Gestore - Il mio account | E30: =COUNTIF('Test Case'!B:B,"Gestore - Il mio account") -> 2
D31: Gestore - Registro presenze | E31: =COUNTIF('Test Case'!B:B,"Gestore - Registro presenze") -> 6
D32: NEXTGEN - Setup | E32: =COUNTIF('Test Case'!B:B,"NEXTGEN - Setup") -> 6
D33: NEXTGEN - Dashboard Genitore | E33: =COUNTIF('Test Case'!B:B,"NEXTGEN - Dashboard Genitore") -> 3
D34: NEXTGEN - Ricerca e scoperta | E34: =COUNTIF('Test Case'!B:B,"NEXTGEN - Ricerca e scoperta") -> 3
D35: NEXTGEN - Planner | E35: =COUNTIF('Test Case'!B:B,"NEXTGEN - Planner") -> 7
D36: NEXTGEN - Home (rifinitura) | E36: =COUNTIF('Test Case'!B:B,"NEXTGEN - Home (rifinitura)") -> 11
D37: Versione LEGACY/NEXTGEN - Toggle | E37: =COUNTIF('Test Case'!B:B,"Versione LEGACY/NEXTGEN - Toggle") -> 5
D38: NEXTGEN - Community | E38: =COUNTIF('Test Case'!B:B,"NEXTGEN - Community") -> 9
D39: TRAMA - Login | E39: =COUNTIF('Test Case'!B:B,"TRAMA - Login") -> 4
